Workbook

Sheet Dashboard
A1: TABLERO DE CONTROL FINANCIERO
A2: AÑO | B2: 2026 | D2: Cambie el año para actualizar todo el modelo
A4: VENTAS ANUALES (ARS) | D4: GANANCIA NETA (ARS) | G4: MARGEN NETO | J4: DIFERENCIA DE CAJA (ARS) | M4: CIERRES A REVISAR
A5: =SUM('Registro Diario'!$L$5:$L$370) -> 330000 | D5: =SUM('Registro Diario'!$O$5:$O$370) -> 54636 | G5: =IFERROR(D5/A5,0) -> 0.16556364 | J5: =SUM('Registro Diario'!$T$5:$T$370) -> 0 | M5: =COUNTIF('Registro Diario'!$V$5:$V$370,"REVISAR CAJA") -> 0
A10: RESULTADOS MENSUALES
A12: MES | B12: VENTAS (ARS) | C12: COSTOS (ARS) | D12: GASTOS (ARS) | E12: GANANCIA (ARS) | F12: MARGEN | G12: DIF. CAJA (ARS)
A13: ENERO | B13: =SUMIFS('Registro Diario'!$L$5:$L$370,'Registro Diario'!$A$5:$A$370,">="&DATE($B$2,1,1),'Registro Diario'!$A$5:$A$370,"<"&EDATE(DATE($B$2,1,1),1)) -> 330000 | C13: =SUMIFS('Registro Diario'!$M$5:$M$370,'Registro Diario'!$A$5:$A$370,">="&DATE($B$2,1,1),'Registro Diario'!$A$5:$A$370,"<"&EDATE(DATE($B$2,1,1),1)) -> 275364 | D13: =SUMIFS('Registro Diario'!$N$5:$N$370,'Registro Diario'!$A$5:$A$370,">="&DATE($B$2,1,1),'Registro Diario'!$A$5:$A$370,"<"&EDATE(DATE($B$2,1,1),1)) -> 0 | E13: =SUMIFS('Registro Diario'!$O$5:$O$370,'Registro Diario'!$A$5:$A$370,">="&DATE($B$2,1,1),'Registro Diario'!$A$5:$A$370,"<"&EDATE(DATE($B$2,1,1),1)) -> 54636 | F13: =IFERROR(E13/B13,0) -> 0.16556364 | G13: =SUMIFS('Registro Diario'!$T$5:$T$370,'Registro Diario'!$A$5:$A$370,">="&DATE($B$2,1,1),'Registro Diario'!$A$5:$A$370,"<"&EDATE(DATE($B$2,1,1),1)) -> 0
A14: FEBRERO | B14: =SUMIFS('Registro Diario'!$L$5:$L$370,'Registro Diario'!$A$5:$A$370,">="&DATE($B$2,2,1),'Registro Diario'!$A$5:$A$370,"<"&EDATE(DATE($B$2,2,1),1)) -> 0 | C14: =SUMIFS('Registro Diario'!$M$5:$M$370,'Registro Diario'!$A$5:$A$370,">="&DATE($B$2,2,1),'Registro Diario'!$A$5:$A$370,"<"&EDATE(DATE($B$2,2,1),1)) -> 0 | D14: =SUMIFS('Registro Diario'!$N$5:$N$370,'Registro Diario'!$A$5:$A$370,">="&DATE($B$2,2,1),'Registro Diario'!$A$5:$A$370,"<"&EDATE(DATE($B$2,2,1),1)) -> 0 | E14: =SUMIFS('Registro Diario'!$O$5:$O$370,'Registro Diario'!$A$5:$A$370,">="&DATE($B$2,2,1),'Registro Diario'!$A$5:$A$370,"<"&EDATE(DATE($B$2,2,1),1)) -> 0 | F14: =IFERROR(E14/B14,0) -> 0 | G14: =SUMIFS('Registro Diario'!$T$5:$T$370,'Registro Diario'!$A$5:$A$370,">="&DATE($B$2,2,1),'Registro Diario'!$A$5:$A$370,"<"&EDATE(DATE($B$2,2,1),1)) -> 0
A15: MARZO | B15: =SUMIFS('Registro Diario'!$L$5:$L$370,'Registro Diario'!$A$5:$A$370,">="&DATE($B$2,3,1),'Registro Diario'!$A$5:$A$370,"<"&EDATE(DATE($B$2,3,1),1)) -> 0 | C15: =SUMIFS('Registro Diario'!$M$5:$M$370,'Registro Diario'!$A$5:$A$370,">="&DATE($B$2,3,1),'Registro Diario'!$A$5:$A$370,"<"&EDATE(DATE($B$2,3,1),1)) -> 0 | D15: =SUMIFS('Registro Diario'!$N$5:$N$370,'Registro Diario'!$A$5:$A$370,">="&DATE($B$2,3,1),'Registro Diario'!$A$5:$A$370,"<"&EDATE(DATE($B$2,3,1),1)) -> 0 | E15: =SUMIFS('Registro Diario'!$O$5:$O$370,'Registro Diario'!$A$5:$A$370,">="&DATE($B$2,3,1),'Registro Diario'!$A$5:$A$370,"<"&EDATE(DATE($B$2,3,1),1)) -> 0 | F15: =IFERROR(E15/B15,0) -> 0 | G15: =SUMIFS('Registro Diario'!$T$5:$T$370,'Registro Diario'!$A$5:$A$370,">="&DATE($B$2,3,1),'Registro Diario'!$A$5:$A$370,"<"&EDATE(DATE($B$2,3,1),1)) -> 0
A16: ABRIL | B16: =SUMIFS('Registro Diario'!$L$5:$L$370,'Registro Diario'!$A$5:$A$370,">="&DATE($B$2,4,1),'Registro Diario'!$A$5:$A$370,"<"&EDATE(DATE($B$2,4,1),1)) -> 0 | C16: =SUMIFS('Registro Diario'!$M$5:$M$370,'Registro Diario'!$A$5:$A$370,">="&DATE($B$2,4,1),'Registro Diario'!$A$5:$A$370,"<"&EDATE(DATE($B$2,4,1),1)) -> 0 | D16: =SUMIFS('Registro Diario'!$N$5:$N$370,'Registro Diario'!$A$5:$A$370,">="&DATE($B$2,4,1),'Registro Diario'!$A$5:$A$370,"<"&EDATE(DATE($B$2,4,1),1)) -> 0 | E16: =SUMIFS('Registro Diario'!$O$5:$O$370,'Registro Diario'!$A$5:$A$370,">="&DATE($B$2,4,1),'Registro Diario'!$A$5:$A$370,"<"&EDATE(DATE($B$2,4,1),1)) -> 0 | F16: =IFERROR(E16/B16,0) -> 0 | G16: =SUMIFS('Registro Diario'!$T$5:$T$370,'Registro Diario'!$A$5:$A$370,">="&DATE($B$2,4,1),'Registro Diario'!$A$5:$A$370,"<"&EDATE(DATE($B$2,4,1),1)) -> 0
A17: MAYO | B17: =SUMIFS('Registro Diario'!$L$5:$L$370,'Registro Diario'!$A$5:$A$370,">="&DATE($B$2,5,1),'Registro Diario'!$A$5:$A$370,"<"&EDATE(DATE($B$2,5,1),1)) -> 0 | C17: =SUMIFS('Registro Diario'!$M$5:$M$370,'Registro Diario'!$A$5:$A$370,">="&DATE($B$2,5,1),'Registro Diario'!$A$5:$A$370,"<"&EDATE(DATE($B$2,5,1),1)) -> 0 | D17: =SUMIFS('Registro Diario'!$N$5:$N$370,'Registro Diario'!$A$5:$A$370,">="&DATE($B$2,5,1),'Registro Diario'!$A$5:$A$370,"<"&EDATE(DATE($B$2,5,1),1)) -> 0 | E17: =SUMIFS('Registro Diario'!$O$5:$O$370,'Registro Diario'!$A$5:$A$370,">="&DATE($B$2,5,1),'Registro Diario'!$A$5:$A$370,"<"&EDATE(DATE($B$2,5,1),1)) -> 0 | F17: =IFERROR(E17/B17,0) -> 0 | G17: =SUMIFS('Registro Diario'!$T$5:$T$370,'Registro Diario'!$A$5:$A$370,">="&DATE($B$2,5,1),'Registro Diario'!$A$5:$A$370,"<"&EDATE(DATE($B$2,5,1),1)) -> 0
A18: JUNIO | B18: =SUMIFS('Registro Diario'!$L$5:$L$370,'Registro Diario'!$A$5:$A$370,">="&DATE($B$2,6,1),'Registro Diario'!$A$5:$A$370,"<"&EDATE(DATE($B$2,6,1),1)) -> 0 | C18: =SUMIFS('Registro Diario'!$M$5:$M$370,'Registro Diario'!$A$5:$A$370,">="&DATE($B$2,6,1),'Registro Diario'!$A$5:$A$370,"<"&EDATE(DATE($B$2,6,1),1)) -> 0 | D18: =SUMIFS('Registro Diario'!$N$5:$N$370,'Registro Diario'!$A$5:$A$370,">="&DATE($B$2,6,1),'Registro Diario'!$A$5:$A$370,"<"&EDATE(DATE($B$2,6,1),1)) -> 0 | E18: =SUMIFS('Registro Diario'!$O$5:$O$370,'Registro Diario'!$A$5:$A$370,">="&DATE($B$2,6,1),'Registro Diario'!$A$5:$A$370,"<"&EDATE(DATE($B$2,6,1),1)) -> 0 | F18: =IFERROR(E18/B18,0) -> 0 | G18: =SUMIFS('Registro Diario'!$T$5:$T$370,'Registro Diario'!$A$5:$A$370,">="&DATE($B$2,6,1),'Registro Diario'!$A$5:$A$370,"<"&EDATE(DATE($B$2,6,1),1)) -> 0
A19: JULIO | B19: =SUMIFS('Registro Diario'!$L$5:$L$370,'Registro Diario'!$A$5:$A$370,">="&DATE($B$2,7,1),'Registro Diario'!$A$5:$A$370,"<"&EDATE(DATE($B$2,7,1),1)) -> 0 | C19: =SUMIFS('Registro Diario'!$M$5:$M$370,'Registro Diario'!$A$5:$A$370,">="&DATE($B$2,7,1),'Registro Diario'!$A$5:$A$370,"<"&EDATE(DATE($B$2,7,1),1)) -> 0 | D19: =SUMIFS('Registro Diario'!$N$5:$N$370,'Registro Diario'!$A$5:$A$370,">="&DATE($B$2,7,1),'Registro Diario'!$A$5:$A$370,"<"&EDATE(DATE($B$2,7,1),1)) -> 0 | E19: =SUMIFS('Registro Diario'!$O$5:$O$370,'Registro Diario'!$A$5:$A$370,">="&DATE($B$2,7,1),'Registro Diario'!$A$5:$A$370,"<"&EDATE(DATE($B$2,7,1),1)) -> 0 | F19: =IFERROR(E19/B19,0) -> 0 | G19: =SUMIFS('Registro Diario'!$T$5:$T$370,'Registro Diario'!$A$5:$A$370,">="&DATE($B$2,7,1),'Registro Diario'!$A$5:$A$370,"<"&EDATE(DATE($B$2,7,1),1)) -> 0
A20: AGOSTO | B20: =SUMIFS('Registro Diario'!$L$5:$L$370,'Registro Diario'!$A$5:$A$370,">="&DATE($B$2,8,1),'Registro Diario'!$A$5:$A$370,"<"&EDATE(DATE($B$2,8,1),1)) -> 0 | C20: =SUMIFS('Registro Diario'!$M$5:$M$370,'Registro Diario'!$A$5:$A$370,">="&DATE($B$2,8,1),'Registro Diario'!$A$5:$A$370,"<"&EDATE(DATE($B$2,8,1),1)) -> 0 | D20: =SUMIFS('Registro Diario'!$N$5:$N$370,'Registro Diario'!$A$5:$A$370,">="&DATE($B$2,8,1),'Registro Diario'!$A$5:$A$370,"<"&EDATE(DATE($B$2,8,1),1)) -> 0 | E20: =SUMIFS('Registro Diario'!$O$5:$O$370,'Registro Diario'!$A$5:$A$370,">="&DATE($B$2,8,1),'Registro Diario'!$A$5:$A$370,"<"&EDATE(DATE($B$2,8,1),1)) -> 0 | F20: =IFERROR(E20/B20,0) -> 0 | G20: =SUMIFS('Registro Diario'!$T$5:$T$370,'Registro Diario'!$A$5:$A$370,">="&DATE($B$2,8,1),'Registro Diario'!$A$5:$A$370,"<"&EDATE(DATE($B$2,8,1),1)) -> 0
A21: SEPTIEMBRE | B21: =SUMIFS('Registro Diario'!$L$5:$L$370,'Registro Diario'!$A$5:$A$370,">="&DATE($B$2,9,1),'Registro Diario'!$A$5:$A$370,"<"&EDATE(DATE($B$2,9,1),1)) -> 0 | C21: =SUMIFS('Registro Diario'!$M$5:$M$370,'Registro Diario'!$A$5:$A$370,">="&DATE($B$2,9,1),'Registro Diario'!$A$5:$A$370,"<"&EDATE(DATE($B$2,9,1),1)) -> 0 | D21: =SUMIFS('Registro Diario'!$N$5:$N$370,'Registro Diario'!$A$5:$A$370,">="&DATE($B$2,9,1),'Registro Diario'!$A$5:$A$370,"<"&EDATE(DATE($B$2,9,1),1)) -> 0 | E21: =SUMIFS('Registro Diario'!$O$5:$O$370,'Registro Diario'!$A$5:$A$370,">="&DATE($B$2,9,1),'Registro Diario'!$A$5:$A$370,"<"&EDATE(DATE($B$2,9,1),1)) -> 0 | F21: =IFERROR(E21/B21,0) -> 0 | G21: =SUMIFS('Registro Diario'!$T$5:$T$370,'Registro Diario'!$A$5:$A$370,">="&DATE($B$2,9,1),'Registro Diario'!$A$5:$A$370,"<"&EDATE(DATE($B$2,9,1),1)) -> 0
A22: OCTUBRE | B22: =SUMIFS('Registro Diario'!$L$5:$L$370,'Registro Diario'!$A$5:$A$370,">="&DATE($B$2,10,1),'Registro Diario'!$A$5:$A$370,"<"&EDATE(DATE($B$2,10,1),1)) -> 0 | C22: =SUMIFS('Registro Diario'!$M$5:$M$370,'Registro Diario'!$A$5:$A$370,">="&DATE($B$2,10,1),'Registro Diario'!$A$5:$A$370,"<"&EDATE(DATE($B$2,10,1),1)) -> 0 | D22: =SUMIFS('Registro Diario'!$N$5:$N$370,'Registro Diario'!$A$5:$A$370,">="&DATE($B$2,10,1),'Registro Diario'!$A$5:$A$370,"<"&EDATE(DATE($B$2,10,1),1)) -> 0 | E22: =SUMIFS('Registro Diario'!$O$5:$O$370,'Registro Diario'!$A$5:$A$370,">="&DATE($B$2,10,1),'Registro Diario'!$A$5:$A$370,"<"&EDATE(DATE($B$2,10,1),1)) -> 0 | F22: =IFERROR(E22/B22,0) -> 0 | G22: =SUMIFS('Registro Diario'!$T$5:$T$370,'Registro Diario'!$A$5:$A$370,">="&DATE($B$2,10,1),'Registro Diario'!$A$5:$A$370,"<"&EDATE(DATE($B$2,10,1),1)) -> 0
A23: NOVIEMBRE | B23: =SUMIFS('Registro Diario'!$L$5:$L$370,'Registro Diario'!$A$5:$A$370,">="&DATE($B$2,11,1),'Registro Diario'!$A$5:$A$370,"<"&EDATE(DATE($B$2,11,1),1)) -> 0 | C23: =SUMIFS('Registro Diario'!$M$5:$M$370,'Registro Diario'!$A$5:$A$370,">="&DATE($B$2,11,1),'Registro Diario'!$A$5:$A$370,"<"&EDATE(DATE($B$2,11,1),1)) -> 0 | D23: =SUMIFS('Registro Diario'!$N$5:$N$370,'Registro Diario'!$A$5:$A$370,">="&DATE($B$2,11,1),'Registro Diario'!$A$5:$A$370,"<"&EDATE(DATE($B$2,11,1),1)) -> 0 | E23: =SUMIFS('Registro Diario'!$O$5:$O$370,'Registro Diario'!$A$5:$A$370,">="&DATE($B$2,11,1),'Registro Diario'!$A$5:$A$370,"<"&EDATE(DATE($B$2,11,1),1)) -> 0 | F23: =IFERROR(E23/B23,0) -> 0 | G23: =SUMIFS('Registro Diario'!$T$5:$T$370,'Registro Diario'!$A$5:$A$370,">="&DATE($B$2,11,1),'Registro Diario'!$A$5:$A$370,"<"&EDATE(DATE($B$2,11,1),1)) -> 0
A24: DICIEMBRE | B24: =SUMIFS('Registro Diario'!$L$5:$L$370,'Registro Diario'!$A$5:$A$370,">="&DATE($B$2,12,1),'Registro Diario'!$A$5:$A$370,"<"&EDATE(DATE($B$2,12,1),1)) -> 0 | C24: =SUMIFS('Registro Diario'!$M$5:$M$370,'Registro Diario'!$A$5:$A$370,">="&DATE($B$2,12,1),'Registro Diario'!$A$5:$A$370,"<"&EDATE(DATE($B$2,12,1),1)) -> 0 | D24: =SUMIFS('Registro Diario'!$N$5:$N$370,'Registro Diario'!$A$5:$A$370,">="&DATE($B$2,12,1),'Registro Diario'!$A$5:$A$370,"<"&EDATE(DATE($B$2,12,1),1)) -> 0 | E24: =SUMIFS('Registro Diario'!$O$5:$O$370,'Registro Diario'!$A$5:$A$370,">="&DATE($B$2,12,1),'Registro Diario'!$A$5:$A$370,"<"&EDATE(DATE($B$2,12,1),1)) -> 0 | F24: =IFERROR(E24/B24,0) -> 0 | G24: =SUMIFS('Registro Diario'!$T$5:$T$370,'Registro Diario'!$A$5:$A$370,">="&DATE($B$2,12,1),'Registro Diario'!$A$5:$A$370,"<"&EDATE(DATE($B$2,12,1),1)) -> 0
A25: TOTAL | B25: =SUM(B13:B24) -> 330000 | C25: =SUM(C13:C24) -> 275364 | D25: =SUM(D13:D24) -> 0 | E25: =SUM(E13:E24) -> 54636 | F25: =IFERROR(E25/B25,0) -> 0.16556364 | G25: =SUM(G13:G24) -> 0
A28: RENDIMIENTO POR PRODUCTO
A30: PRODUCTO | B30: UNIDADES | C30: VENTAS (ARS) | D30: UTILIDAD BRUTA (ARS) | E30: MIX VENTAS | F30: MARGEN CONTRIB. | G30: ESTADO
A31: KEBAB | B31: =SUM('Registro Diario'!$C$5:$C$370) -> 5 | C31: =B31*'Menu Productos'!$F$5 -> 50000 | D31: =B31*'Menu Productos'!$G$5 -> 7430 | E31: =IFERROR(C31/SUM($C$31:$C$38),0) -> 0.15151515 | F31: ='Menu Productos'!H5 -> 0.1486 | G31: =IF(B31=0,"SIN VENTAS",IF(F31<15%,"REVISAR",IF(F31<=25%,"ACEPTABLE","SALUDABLE"))) -> REVISAR
A32: COMBO N1 | B32: =SUM('Registro Diario'!$D$5:$D$370) -> 1 | C32: =B32*'Menu Productos'!$F$6 -> 12500 | D32: =B32*'Menu Productos'!$G$6 -> 2486 | E32: =IFERROR(C32/SUM($C$31:$C$38),0) -> 0.037878788 | F32: ='Menu Productos'!H6 -> 0.19888 | G32: =IF(B32=0,"SIN VENTAS",IF(F32<15%,"REVISAR",IF(F32<=25%,"ACEPTABLE","SALUDABLE"))) -> ACEPTABLE
A33: COMBO N2 | B33: =SUM('Registro Diario'!$E$5:$E$370) -> 5 | C33: =B33*'Menu Productos'!$F$7 -> 110000 | D33: =B33*'Menu Productos'!$G$7 -> 17360 | E33: =IFERROR(C33/SUM($C$31:$C$38),0) -> 0.33333333 | F33: ='Menu Productos'!H7 -> 0.15781818 | G33: =IF(B33=0,"SIN VENTAS",IF(F33<15%,"REVISAR",IF(F33<=25%,"ACEPTABLE","SALUDABLE"))) -> ACEPTABLE
A34: BOX COMUN | B34: =SUM('Registro Diario'!$F$5:$F$370) -> 10 | C34: =B34*'Menu Productos'!$F$8 -> 100000 | D34: =B34*'Menu Productos'!$G$8 -> 14860 | E34: =IFERROR(C34/SUM($C$31:$C$38),0) -> 0.3030303 | F34: ='Menu Productos'!H8 -> 0.1486 | G34: =IF(B34=0,"SIN VENTAS",IF(F34<15%,"REVISAR",IF(F34<=25%,"ACEPTABLE","SALUDABLE"))) -> REVISAR
A35: BOX XL | B35: =SUM('Registro Diario'!$G$5:$G$370) -> 3 | C35: =B35*'Menu Productos'!$F$9 -> 39000 | D35: =B35*'Menu Productos'!$G$9 -> 7500 | E35: =IFERROR(C35/SUM($C$31:$C$38),0) -> 0.11818182 | F35: ='Menu Productos'!H9 -> 0.19230769 | G35: =IF(B35=0,"SIN VENTAS",IF(F35<15%,"REVISAR",IF(F35<=25%,"ACEPTABLE","SALUDABLE"))) -> ACEPTABLE
A36: PREMIUM | B36: =SUM('Registro Diario'!$H$5:$H$370) -> 0 | C36: =B36*'Menu Productos'!$F$10 -> 0 | D36: =B36*'Menu Productos'!$G$10 -> 0 | E36: =IFERROR(C36/SUM($C$31:$C$38),0) -> 0 | F36: ='Menu Productos'!H10 -> 0.23076923 | G36: =IF(B36=0,"SIN VENTAS",IF(F36<15%,"REVISAR",IF(F36<=25%,"ACEPTABLE","SALUDABLE"))) -> SIN VENTAS
A37: TOPPINGS | B37: =SUM('Registro Diario'!$I$5:$I$370) -> 15 | C37: =B37*'Menu Productos'!$F$11 -> 4500 | D37: =B37*'Menu Productos'!$G$11 -> 1500 | E37: =IFERROR(C37/SUM($C$31:$C$38),0) -> 0.013636364 | F37: ='Menu Productos'!H11 -> 0.33333333 | G37: =IF(B37=0,"SIN VENTAS",IF(F37<15%,"REVISAR",IF(F37<=25%,"ACEPTABLE","SALUDABLE"))) -> SALUDABLE
A38: PAPA FRITAS | B38: =SUM('Registro Diario'!$J$5:$J$370) -> 7 | C38: =B38*'Menu Productos'!$F$12 -> 14000 | D38: =B38*'Menu Productos'!$G$12 -> 3500 | E38: =IFERROR(C38/SUM($C$31:$C$38),0) -> 0.042424242 | F38: ='Menu Productos'!H12 -> 0.25 | G38: =IF(B38=0,"SIN VENTAS",IF(F38<15%,"REVISAR",IF(F38<=25%,"ACEPTABLE","SALUDABLE"))) -> ACEPTABLE
A39: TOTAL | B39: =SUM(B31:B38) -> 46 | C39: =SUM(C31:C38) -> 330000 | D39: =SUM(D31:D38) -> 54636 | E39: =SUM(E31:E38) -> 1 | F39: =IFERROR(D39/C39,0) -> 0.16556364 | G39: PORTAFOLIO
A42: MEDIOS DE COBRO | E42: CONTROL OPERATIVO | I42: METAS Y PROYECCIÓN
A44: MEDIO | B44: MONTO (ARS) | C44: PARTICIPACIÓN | E44: DÍAS CON VENTAS | F44: =COUNTIF('Registro Diario'!$K$5:$K$370,">0") -> 1 | I44: META ANUAL VENTAS | M44: ='Metas y Control'!C23 -> 4356000
A45: EFECTIVO | B45: =SUM('Registro Diario'!$P$5:$P$370) -> 300000 | C45: =IFERROR(B45/$B$48,0) -> 0.90909091 | E45: VENTA PROMEDIO / DÍA | F45: =IFERROR(SUM('Registro Diario'!$L$5:$L$370)/F44,0) -> 330000 | I45: CUMPLIMIENTO ANUAL | M45: =IFERROR(A5/M44,0) -> 0.075757576
A46: TRANSFERENCIA | B46: =SUM('Registro Diario'!$Q$5:$Q$370) -> 0 | C46: =IFERROR(B46/$B$48,0) -> 0 | E46: UNIDADES VENDIDAS | F46: =SUM('Registro Diario'!$K$5:$K$370) -> 46 | I46: PROYECCIÓN ANUAL | M46: =IFERROR(A5/COUNTIF(B13:B24,">0")*12,0) -> 3960000
A47: MERCADO PAGO | B47: =SUM('Registro Diario'!$R$5:$R$370) -> 30000 | C47: =IFERROR(B47/$B$48,0) -> 0.090909091 | E47: CIERRES A REVISAR | F47: =COUNTIF('Registro Diario'!$V$5:$V$370,"REVISAR CAJA") -> 0 | I47: PUNTO EQUILIBRIO MENSUAL | M47: ='Metas y Control'!H23 -> 0
A48: TOTAL | B48: =SUM(B45:B47) -> 330000 | C48: =SUM(C45:C47) -> 1 | E48: DÍAS SIN MOVIMIENTO | F48: =COUNTIFS('Registro Diario'!$A$5:$A$370,"<="&TODAY(),'Registro Diario'!$V$5:$V$370,"SIN MOVIMIENTO") -> 265

Sheet Registro Diario
A1: CIERRES DE CAJA — REGISTRO DIARIO
A2: Complete cantidades, gastos y medios de cobro. Las columnas azules se calculan automáticamente.
A4: FECHA | B4: MES | C4: KEBAB | D4: COMBO N1 | E4: COMBO N2 | F4: BOX COMUN | G4: BOX XL | H4: PREMIUM | I4: TOPPINGS | J4: PAPA FRITAS | K4: TOTAL UNIDADES | L4: VENTA TOTAL | M4: COSTO TOTAL | N4: GASTOS | O4: GANANCIA NETA | P4: EFECTIVO | Q4: TRANSFERENCIA | R4: MERCADO PAGO | S4: TOTAL COBRADO | T4: DIFERENCIA CAJA | U4: OBSERVACIONES | V4: ESTADO
A5: =DATE(Dashboard!$B$2,1,1) -> 46023 | B5: =IF(A5="","",TEXT(A5,"mmmm")) -> enero | C5: 5 | D5: 1 | E5: 5 | F5: 10 | G5: 3 | H5: 0 | I5: 15 | J5: 7 | K5: =IF(A5="","",SUM(C5:J5)) -> 46 | L5: =IF(A5="","",C5*'Menu Productos'!$F$5+D5*'Menu Productos'!$F$6+E5*'Menu Productos'!$F$7+F5*'Menu Productos'!$F$8+G5*'Menu Productos'!$F$9+H5*'Menu Productos'!$F$10+I5*'Menu Productos'!$F$11+J5*'Menu Productos'!$F$12) -> 330000 | M5: =IF(A5="","",C5*'Menu Productos'!$E$5+D5*'Menu Productos'!$E$6+E5*'Menu Productos'!$E$7+F5*'Menu Productos'!$E$8+G5*'Menu Productos'!$E$9+H5*'Menu Productos'!$E$10+I5*'Menu Productos'!$E$11+J5*'Menu Productos'!$E$12) -> 275364 | O5: =IF(A5="","",L5-M5-N5) -> 54636 | P5: 300000 | Q5: - | R5: 30000 | S5: =IF(A5="","",SUM(P5:R5)) -> 330000 | T5: =IF(A5="","",S5-(L5-N5)) -> 0 | V5: =IF(A5>TODAY(),"FUTURO",IF(AND(K5=0,N5=0,S5=0),"SIN MOVIMIENTO",IF(ABS(T5)<='Metas y Control'!$B$6,"OK","REVISAR CAJA"))) -> OK
A6: =IF(YEAR(A5+1)=Dashboard!$B$2,A5+1,"") -> 46024 | B6: =IF(A6="","",TEXT(A6,"mmmm")) -> enero | K6: =IF(A6="","",SUM(C6:J6)) -> 0 | L6: =IF(A6="","",C6*'Menu Productos'!$F$5+D6*'Menu Productos'!$F$6+E6*'Menu Productos'!$F$7+F6*'Menu Productos'!$F$8+G6*'Menu Productos'!$F$9+H6*'Menu Productos'!$F$10+I6*'Menu Productos'!$F$11+J6*'Menu Productos'!$F$12) -> 0 | M6: =IF(A6="","",C6*'Menu Productos'!$E$5+D6*'Menu Productos'!$E$6+E6*'Menu Productos'!$E$7+F6*'Menu Productos'!$E$8+G6*'Menu Productos'!$E$9+H6*'Menu Productos'!$E$10+I6*'Menu Productos'!$E$11+J6*'Menu Productos'!$E$12) -> 0 | O6: =IF(A6="","",L6-M6-N6) -> 0 | S6: =IF(A6="","",SUM(P6:R6)) -> 0 | T6: =IF(A6="","",S6-(L6-N6)) -> 0 | V6: =IF(A6>TODAY(),"FUTURO",IF(AND(K6=0,N6=0,S6=0),"SIN MOVIMIENTO",IF(ABS(T6)<='Metas y Control'!$B$6,"OK","REVISAR CAJA"))) -> SIN MOVIMIENTO
A7: =IF(YEAR(A6+1)=Dashboard!$B$2,A6+1,"") -> 46025 | B7: =IF(A7="","",TEXT(A7,"mmmm")) -> enero | K7: =IF(A7="","",SUM(C7:J7)) -> 0 | L7: =IF(A7="","",C7*'Menu Productos'!$F$5+D7*'Menu Productos'!$F$6+E7*'Menu Productos'!$F$7+F7*'Menu Productos'!$F$8+G7*'Menu Productos'!$F$9+H7*'Menu Productos'!$F$10+I7*'Menu Productos'!$F$11+J7*'Menu Productos'!$F$12) -> 0 | M7: =IF(A7="","",C7*'Menu Productos'!$E$5+D7*'Menu Productos'!$E$6+E7*'Menu Productos'!$E$7+F7*'Menu Productos'!$E$8+G7*'Menu Productos'!$E$9+H7*'Menu Productos'!$E$10+I7*'Menu Productos'!$E$11+J7*'Menu Productos'!$E$12) -> 0 | O7: =IF(A7="","",L7-M7-N7) -> 0 | S7: =IF(A7="","",SUM(P7:R7)) -> 0 | T7: =IF(A7="","",S7-(L7-N7)) -> 0 | V7: =IF(A7>TODAY(),"FUTURO",IF(AND(K7=0,N7=0,S7=0),"SIN MOVIMIENTO",IF(ABS(T7)<='Metas y Control'!$B$6,"OK","REVISAR CAJA"))) -> SIN MOVIMIENTO
A8: =IF(YEAR(A7+1)=Dashboard!$B$2,A7+1,"") -> 46026 | B8: =IF(A8="","",TEXT(A8,"mmmm")) -> enero | K8: =IF(A8="","",SUM(C8:J8)) -> 0 | L8: =IF(A8="","",C8*'Menu Productos'!$F$5+D8*'Menu Productos'!$F$6+E8*'Menu Productos'!$F$7+F8*'Menu Productos'!$F$8+G8*'Menu Productos'!$F$9+H8*'Menu Productos'!$F$10+I8*'Menu Productos'!$F$11+J8*'Menu Productos'!$F$12) -> 0 | M8: =IF(A8="","",C8*'Menu Productos'!$E$5+D8*'Menu Productos'!$E$6+E8*'Menu Productos'!$E$7+F8*'Menu Productos'!$E$8+G8*'Menu Productos'!$E$9+H8*'Menu Productos'!$E$10+I8*'Menu Productos'!$E$11+J8*'Menu Productos'!$E$12) -> 0 | O8: =IF(A8="","",L8-M8-N8) -> 0 | S8: =IF(A8="","",SUM(P8:R8)) -> 0 | T8: =IF(A8="","",S8-(L8-N8)) -> 0 | V8: =IF(A8>TODAY(),"FUTURO",IF(AND(K8=0,N8=0,S8=0),"SIN MOVIMIENTO",IF(ABS(T8)<='Metas y Control'!$B$6,"OK","REVISAR CAJA"))) -> SIN MOVIMIENTO
A9: =IF(YEAR(A8+1)=Dashboard!$B$2,A8+1,"") -> 46027 | B9: =IF(A9="","",TEXT(A9,"mmmm")) -> enero | K9: =IF(A9="","",SUM(C9:J9)) -> 0 | L9: =IF(A9="","",C9*'Menu Productos'!$F$5+D9*'Menu Productos'!$F$6+E9*'Menu Productos'!$F$7+F9*'Menu Productos'!$F$8+G9*'Menu Productos'!$F$9+H9*'Menu Productos'!$F$10+I9*'Menu Productos'!$F$11+J9*'Menu Productos'!$F$12) -> 0 | M9: =IF(A9="","",C9*'Menu Productos'!$E$5+D9*'Menu Productos'!$E$6+E9*'Menu Productos'!$E$7+F9*'Menu Productos'!$E$8+G9*'Menu Productos'!$E$9+H9*'Menu Productos'!$E$10+I9*'Menu Productos'!$E$11+J9*'Menu Productos'!$E$12) -> 0 | O9: =IF(A9="","",L9-M9-N9) -> 0 | S9: =IF(A9="","",SUM(P9:R9)) -> 0 | T9: =IF(A9="","",S9-(L9-N9)) -> 0 | V9: =IF(A9>TODAY(),"FUTURO",IF(AND(K9=0,N9=0,S9=0),"SIN MOVIMIENTO",IF(ABS(T9)<='Metas y Control'!$B$6,"OK","REVISAR CAJA"))) -> SIN MOVIMIENTO
A10: =IF(YEAR(A9+1)=Dashboard!$B$2,A9+1,"") -> 46028 | B10: =IF(A10="","",TEXT(A10,"mmmm")) -> enero | K10: =IF(A10="","",SUM(C10:J10)) -> 0 | L10: =IF(A10="","",C10*'Menu Productos'!$F$5+D10*'Menu Productos'!$F$6+E10*'Menu Productos'!$F$7+F10*'Menu Productos'!$F$8+G10*'Menu Productos'!$F$9+H10*'Menu Productos'!$F$10+I10*'Menu Productos'!$F$11+J10*'Menu Productos'!$F$12) -> 0 | M10: =IF(A10="","",C10*'Menu Productos'!$E$5+D10*'Menu Productos'!$E$6+E10*'Menu Productos'!$E$7+F10*'Menu Productos'!$E$8+G10*'Menu Productos'!$E$9+H10*'Menu Productos'!$E$10+I10*'Menu Productos'!$E$11+J10*'Menu Productos'!$E$12) -> 0 | O10: =IF(A10="","",L10-M10-N10) -> 0 | S10: =IF(A10="","",SUM(P10:R10)) -> 0 | T10: =IF(A10="","",S10-(L10-N10)) -> 0 | V10: =IF(A10>TODAY(),"FUTURO",IF(AND(K10=0,N10=0,S10=0),"SIN MOVIMIENTO",IF(ABS(T10)<='Metas y Control'!$B$6,"OK","REVISAR CAJA"))) -> SIN MOVIMIENTO
A11: =IF(YEAR(A10+1)=Dashboard!$B$2,A10+1,"") -> 46029 | B11: =IF(A11="","",TEXT(A11,"mmmm")) -> enero | K11: =IF(A11="","",SUM(C11:J11)) -> 0 | L11: =IF(A11="","",C11*'Menu Productos'!$F$5+D11*'Menu Productos'!$F$6+E11*'Menu Productos'!$F$7+F11*'Menu Productos'!$F$8+G11*'Menu Productos'!$F$9+H11*'Menu Productos'!$F$10+I11*'Menu Productos'!$F$11+J11*'Menu Productos'!$F$12) -> 0 | M11: =IF(A11="","",C11*'Menu Productos'!$E$5+D11*'Menu Productos'!$E$6+E11*'Menu Productos'!$E$7+F11*'Menu Productos'!$E$8+G11*'Menu Productos'!$E$9+H11*'Menu Productos'!$E$10+I11*'Menu Productos'!$E$11+J11*'Menu Productos'!$E$12) -> 0 | O11: =IF(A11="","",L11-M11-N11) -> 0 | S11: =IF(A11="","",SUM(P11:R11)) -> 0 | T11: =IF(A11="","",S11-(L11-N11)) -> 0 | V11: =IF(A11>TODAY(),"FUTURO",IF(AND(K11=0,N11=0,S11=0),"SIN MOVIMIENTO",IF(ABS(T11)<='Metas y Control'!$B$6,"OK","REVISAR CAJA"))) -> SIN MOVIMIENTO
A12: =IF(YEAR(A11+1)=Dashboard!$B$2,A11+1,"") -> 46030 | B12: =IF(A12="","",TEXT(A12,"mmmm")) -> enero | K12: =IF(A12="","",SUM(C12:J12)) -> 0 | L12: =IF(A12="","",C12*'Menu Productos'!$F$5+D12*'Menu Productos'!$F$6+E12*'Menu Productos'!$F$7+F12*'Menu Productos'!$F$8+G12*'Menu Productos'!$F$9+H12*'Menu Productos'!$F$10+I12*'Menu Productos'!$F$11+J12*'Menu Productos'!$F$12) -> 0 | M12: =IF(A12="","",C12*'Menu Productos'!$E$5+D12*'Menu Productos'!$E$6+E12*'Menu Productos'!$E$7+F12*'Menu Productos'!$E$8+G12*'Menu Productos'!$E$9+H12*'Menu Productos'!$E$10+I12*'Menu Productos'!$E$11+J12*'Menu Productos'!$E$12) -> 0 | O12: =IF(A12="","",L12-M12-N12) -> 0 | S12: =IF(A12="","",SUM(P12:R12)) -> 0 | T12: =IF(A12="","",S12-(L12-N12)) -> 0 | V12: =IF(A12>TODAY(),"FUTURO",IF(AND(K12=0,N12=0,S12=0),"SIN MOVIMIENTO",IF(ABS(T12)<='Metas y Control'!$B$6,"OK","REVISAR CAJA"))) -> SIN MOVIMIENTO
A13: =IF(YEAR(A12+1)=Dashboard!$B$2,A12+1,"") -> 46031 | B13: =IF(A13="","",TEXT(A13,"mmmm")) -> enero | K13: =IF(A13="","",SUM(C13:J13)) -> 0 | L13: =IF(A13="","",C13*'Menu Productos'!$F$5+D13*'Menu Productos'!$F$6+E13*'Menu Productos'!$F$7+F13*'Menu Productos'!$F$8+G13*'Menu Productos'!$F$9+H13*'Menu Productos'!$F$10+I13*'Menu Productos'!$F$11+J13*'Menu Productos'!$F$12) -> 0 | M13: =IF(A13="","",C13*'Menu Productos'!$E$5+D13*'Menu Productos'!$E$6+E13*'Menu Productos'!$E$7+F13*'Menu Productos'!$E$8+G13*'Menu Productos'!$E$9+H13*'Menu Productos'!$E$10+I13*'Menu Productos'!$E$11+J13*'Menu Productos'!$E$12) -> 0 | O13: =IF(A13="","",L13-M13-N13) -> 0 | S13: =IF(A13="","",SUM(P13:R13)) -> 0 | T13: =IF(A13="","",S13-(L13-N13)) -> 0 | V13: =IF(A13>TODAY(),"FUTURO",IF(AND(K13=0,N13=0,S13=0),"SIN MOVIMIENTO",IF(ABS(T13)<='Metas y Control'!$B$6,"OK","REVISAR CAJA"))) -> SIN MOVIMIENTO
A14: =IF(YEAR(A13+1)=Dashboard!$B$2,A13+1,"") -> 46032 | B14: =IF(A14="","",TEXT(A14,"mmmm")) -> enero | K14: =IF(A14="","",SUM(C14:J14)) -> 0 | L14: =IF(A14="","",C14*'Menu Productos'!$F$5+D14*'Menu Productos'!$F$6+E14*'Menu Productos'!$F$7+F14*'Menu Productos'!$F$8+G14*'Menu Productos'!$F$9+H14*'Menu Productos'!$F$10+I14*'Menu Productos'!$F$11+J14*'Menu Productos'!$F$12) -> 0 | M14: =IF(A14="","",C14*'Menu Productos'!$E$5+D14*'Menu Productos'!$E$6+E14*'Menu Productos'!$E$7+F14*'Menu Productos'!$E$8+G14*'Menu Productos'!$E$9+H14*'Menu Productos'!$E$10+I14*'Menu Productos'!$E$11+J14*'Menu Productos'!$E$12) -> 0 | O14: =IF(A14="","",L14-M14-N14) -> 0 | S14: =IF(A14="","",SUM(P14:R14)) -> 0 | T14: =IF(A14="","",S14-(L14-N14)) -> 0 | V14: =IF(A14>TODAY(),"FUTURO",IF(AND(K14=0,N14=0,S14=0),"SIN MOVIMIENTO",IF(ABS(T14)<='Metas y Control'!$B$6,"OK","REVISAR CAJA"))) -> SIN MOVIMIENTO
A15: =IF(YEAR(A14+1)=Dashboard!$B$2,A14+1,"") -> 46033 | B15: =IF(A15="","",TEXT(A15,"mmmm")) -> enero | K15: =IF(A15="","",SUM(C15:J15)) -> 0 | L15: =IF(A15="","",C15*'Menu Productos'!$F$5+D15*'Menu Productos'!$F$6+E15*'Menu Productos'!$F$7+F15*'Menu Productos'!$F$8+G15*'Menu Productos'!$F$9+H15*'Menu Productos'!$F$10+I15*'Menu Productos'!$F$11+J15*'Menu Productos'!$F$12) -> 0 | M15: =IF(A15="","",C15*'Menu Productos'!$E$5+D15*'Menu Productos'!$E$6+E15*'Menu Productos'!$E$7+F15*'Menu Productos'!$E$8+G15*'Menu Productos'!$E$9+H15*'Menu Productos'!$E$10+I15*'Menu Productos'!$E$11+J15*'Menu Productos'!$E$12) -> 0 | O15: =IF(A15="","",L15-M15-N15) -> 0 | S15: =IF(A15="","",SUM(P15:R15)) -> 0 | T15: =IF(A15="","",S15-(L15-N15)) -> 0 | V15: =IF(A15>TODAY(),"FUTURO",IF(AND(K15=0,N15=0,S15=0),"SIN MOVIMIENTO",IF(ABS(T15)<='Metas y Control'!$B$6,"OK","REVISAR CAJA"))) -> SIN MOVIMIENTO
A16: =IF(YEAR(A15+1)=Dashboard!$B$2,A15+1,"") -> 46034 | B16: =IF(A16="","",TEXT(A16,"mmmm")) -> enero | K16: =IF(A16="","",SUM(C16:J16)) -> 0 | L16: =IF(A16="","",C16*'Menu Productos'!$F$5+D16*'Menu Productos'!$F$6+E16*'Menu Productos'!$F$7+F16*'Menu Productos'!$F$8+G16*'Menu Productos'!$F$9+H16*'Menu Productos'!$F$10+I16*'Menu Productos'!$F$11+J16*'Menu Productos'!$F$12) -> 0 | M16: =IF(A16="","",C16*'Menu Productos'!$E$5+D16*'Menu Productos'!$E$6+E16*'Menu Productos'!$E$7+F16*'Menu Productos'!$E$8+G16*'Menu Productos'!$E$9+H16*'Menu Productos'!$E$10+I16*'Menu Productos'!$E$11+J16*'Menu Productos'!$E$12) -> 0 | O16: =IF(A16="","",L16-M16-N16) -> 0 | S16: =IF(A16="","",SUM(P16:R16)) -> 0 | T16: =IF(A16="","",S16-(L16-N16)) -> 0 | V16: =IF(A16>TODAY(),"FUTURO",IF(AND(K16=0,N16=0,S16=0),"SIN MOVIMIENTO",IF(ABS(T16)<='Metas y Control'!$B$6,"OK","REVISAR CAJA"))) -> SIN MOVIMIENTO
A17: =IF(YEAR(A16+1)=Dashboard!$B$2,A16+1,"") -> 46035 | B17: =IF(A17="","",TEXT(A17,"mmmm")) -> enero | K17: =IF(A17="","",SUM(C17:J17)) -> 0 | L17: =IF(A17="","",C17*'Menu Productos'!$F$5+D17*'Menu Productos'!$F$6+E17*'Menu Productos'!$F$7+F17*'Menu Productos'!$F$8+G17*'Menu Productos'!$F$9+H17*'Menu Productos'!$F$10+I17*'Menu Productos'!$F$11+J17*'Menu Productos'!$F$12) -> 0 | M17: =IF(A17="","",C17*'Menu Productos'!$E$5+D17*'Menu Productos'!$E$6+E17*'Menu Productos'!$E$7+F17*'Menu Productos'!$E$8+G17*'Menu Productos'!$E$9+H17*'Menu Productos'!$E$10+I17*'Menu Productos'!$E$11+J17*'Menu Productos'!$E$12) -> 0 | O17: =IF(A17="","",L17-M17-N17) -> 0 | S17: =IF(A17="","",SUM(P17:R17)) -> 0 | T17: =IF(A17="","",S17-(L17-N17)) -> 0 | V17: =IF(A17>TODAY(),"FUTURO",IF(AND(K17=0,N17=0,S17=0),"SIN MOVIMIENTO",IF(ABS(T17)<='Metas y Control'!$B$6,"OK","REVISAR CAJA"))) -> SIN MOVIMIENTO
... A370: =IF(YEAR(A369+1)=Dashboard!$B$2,A369+1,"") | B370: =IF(A370="","",TEXT(A370,"mmmm")) | K370: =IF(A370="","",SUM(C370:J370)) | L370: =IF(A370="","",C370*'Menu Productos'!$F$5+D370*'Menu Productos'!$F$6+E370*'Menu Productos'!$F$7+F370*'Menu Productos'!$F$8+G370*'Menu Productos'!$F$9+H370*'Menu Productos'!$F$10+I370*'Menu Productos'!$F$11+J370*'Menu Productos'!$F$12) | M370: =IF(A370="","",C370*'Menu Productos'!$E$5+D370*'Menu Productos'!$E$6+E370*'Menu Productos'!$E$7+F370*'Menu Productos'!$E$8+G370*'Menu Productos'!$E$9+H370*'Menu Productos'!$E$10+I370*'Menu Productos'!$E$11+J370*'Menu Productos'!$E$12) | O370: =IF(A370="","",L370-M370-N370) | S370: =IF(A370="","",SUM(P370:R370)) | T370: =IF(A370="","",S370-(L370-N370)) | V370: =IF(A370>TODAY(),"FUTURO",IF(AND(K370=0,N370=0,S370=0),"SIN MOVIMIENTO",IF(ABS(T370)<='Metas y Control'!$B$6,"OK","REVISAR CAJA"))) -> FUTURO

Sheet Menu Productos
A1: MENÚ Y ESTRUCTURA DE COSTOS
A2: Edite únicamente las celdas amarillas. Los costos y márgenes se recalculan automáticamente.
A4: PRODUCTO | B4: COSTO INSUMOS | C4: EXTRA / PAPAS | D4: COSTO OPERATIVO UNIT. | E4: COSTO TOTAL | F4: PRECIO VENTA | G4: UTILIDAD UNITARIA | H4: MARGEN CONTRIB. | I4: MARKUP
A5: KEBAB | B5: 6014 | C5: 0 | D5: 2500 | E5: =SUM(B5:D5) -> 8514 | F5: 10000 | G5: =F5-E5 -> 1486 | H5: =IFERROR(G5/F5,0) -> 0.1486 | I5: =IFERROR(F5/E5-1,0) -> 0.17453606
A6: COMBO N1 | B6: 6014 | C6: 1500 | D6: 2500 | E6: =SUM(B6:D6) -> 10014 | F6: 12500 | G6: =F6-E6 -> 2486 | H6: =IFERROR(G6/F6,0) -> 0.19888 | I6: =IFERROR(F6/E6-1,0) -> 0.24825245
A7: COMBO N2 | B7: 12028 | C7: 1500 | D7: 5000 | E7: =SUM(B7:D7) -> 18528 | F7: 22000 | G7: =F7-E7 -> 3472 | H7: =IFERROR(G7/F7,0) -> 0.15781818 | I7: =IFERROR(F7/E7-1,0) -> 0.18739206
A8: BOX COMUN | B8: 6014 | C8: 0 | D8: 2500 | E8: =SUM(B8:D8) -> 8514 | F8: 10000 | G8: =F8-E8 -> 1486 | H8: =IFERROR(G8/F8,0) -> 0.1486 | I8: =IFERROR(F8/E8-1,0) -> 0.17453606
A9: BOX XL | B9: 8000 | C9: 0 | D9: 2500 | E9: =SUM(B9:D9) -> 10500 | F9: 13000 | G9: =F9-E9 -> 2500 | H9: =IFERROR(G9/F9,0) -> 0.19230769 | I9: =IFERROR(F9/E9-1,0) -> 0.23809524
A10: PREMIUM | B10: 6500 | C10: 1500 | D10: 2000 | E10: =SUM(B10:D10) -> 10000 | F10: 13000 | G10: =F10-E10 -> 3000 | H10: =IFERROR(G10/F10,0) -> 0.23076923 | I10: =IFERROR(F10/E10-1,0) -> 0.3
A11: TOPPINGS | B11: 200 | C11: 0 | D11: 0 | E11: =SUM(B11:D11) -> 200 | F11: 300 | G11: =F11-E11 -> 100 | H11: =IFERROR(G11/F11,0) -> 0.33333333 | I11: =IFERROR(F11/E11-1,0) -> 0.5
A12: PAPA FRITAS | B12: 1500 | C12: 0 | D12: 0 | E12: =SUM(B12:D12) -> 1500 | F12: 2000 | G12: =F12-E12 -> 500 | H12: =IFERROR(G12/F12,0) -> 0.25 | I12: =IFERROR(F12/E12-1,0) -> 0.33333333

Sheet Metas y Control
A1: METAS Y CONTROL DEL NEGOCIO
A2: Las celdas amarillas son supuestos editables; el resto se actualiza desde el registro diario.
A4: CRECIMIENTO OBJETIVO | B4: 0.1
A5: MARGEN NETO OBJETIVO | B5: 0.2
A6: TOLERANCIA DE CAJA (ARS) | B6: 1
A7: GASTOS FIJOS MENSUALES | B7: =IFERROR(AVERAGEIF(Dashboard!$D$13:$D$24,">0"),0) -> 0
A10: MES | B10: VENTAS REALES (ARS) | C10: META VENTAS (ARS) | D10: CUMPLIMIENTO | E10: GANANCIA REAL (ARS) | F10: META GANANCIA (ARS) | G10: BRECHA GANANCIA (ARS) | H10: PUNTO EQUILIBRIO (ARS)
A11: =Dashboard!A13 -> ENERO | B11: =Dashboard!B13 -> 330000 | C11: =IFERROR(AVERAGEIF(Dashboard!$B$13:$B$24,">0")*(1+$B$4),0) -> 363000 | D11: =IFERROR(B11/C11,0) -> 0.90909091 | E11: =Dashboard!E13 -> 54636 | F11: =C11*$B$5 -> 72600 | G11: =E11-F11 -> -17964 | H11: =IFERROR($B$7/SUMPRODUCT(Dashboard!$E$31:$E$38,'Menu Productos'!$H$5:$H$12),0) -> 0
A12: =Dashboard!A14 -> FEBRERO | B12: =Dashboard!B14 -> 0 | C12: =IFERROR(AVERAGEIF(Dashboard!$B$13:$B$24,">0")*(1+$B$4),0) -> 363000 | D12: =IFERROR(B12/C12,0) -> 0 | E12: =Dashboard!E14 -> 0 | F12: =C12*$B$5 -> 72600 | G12: =E12-F12 -> -72600 | H12: =IFERROR($B$7/SUMPRODUCT(Dashboard!$E$31:$E$38,'Menu Productos'!$H$5:$H$12),0) -> 0
A13: =Dashboard!A15 -> MARZO | B13: =Dashboard!B15 -> 0 | C13: =IFERROR(AVERAGEIF(Dashboard!$B$13:$B$24,">0")*(1+$B$4),0) -> 363000 | D13: =IFERROR(B13/C13,0) -> 0 | E13: =Dashboard!E15 -> 0 | F13: =C13*$B$5 -> 72600 | G13: =E13-F13 -> -72600 | H13: =IFERROR($B$7/SUMPRODUCT(Dashboard!$E$31:$E$38,'Menu Productos'!$H$5:$H$12),0) -> 0
A14: =Dashboard!A16 -> ABRIL | B14: =Dashboard!B16 -> 0 | C14: =IFERROR(AVERAGEIF(Dashboard!$B$13:$B$24,">0")*(1+$B$4),0) -> 363000 | D14: =IFERROR(B14/C14,0) -> 0 | E14: =Dashboard!E16 -> 0 | F14: =C14*$B$5 -> 72600 | G14: =E14-F14 -> -72600 | H14: =IFERROR($B$7/SUMPRODUCT(Dashboard!$E$31:$E$38,'Menu Productos'!$H$5:$H$12),0) -> 0
A15: =Dashboard!A17 -> MAYO | B15: =Dashboard!B17 -> 0 | C15: =IFERROR(AVERAGEIF(Dashboard!$B$13:$B$24,">0")*(1+$B$4),0) -> 363000 | D15: =IFERROR(B15/C15,0) -> 0 | E15: =Dashboard!E17 -> 0 | F15: =C15*$B$5 -> 72600 | G15: =E15-F15 -> -72600 | H15: =IFERROR($B$7/SUMPRODUCT(Dashboard!$E$31:$E$38,'Menu Productos'!$H$5:$H$12),0) -> 0
A16: =Dashboard!A18 -> JUNIO | B16: =Dashboard!B18 -> 0 | C16: =IFERROR(AVERAGEIF(Dashboard!$B$13:$B$24,">0")*(1+$B$4),0) -> 363000 | D16: =IFERROR(B16/C16,0) -> 0 | E16: =Dashboard!E18 -> 0 | F16: =C16*$B$5 -> 72600 | G16: =E16-F16 -> -72600 | H16: =IFERROR($B$7/SUMPRODUCT(Dashboard!$E$31:$E$38,'Menu Productos'!$H$5:$H$12),0) -> 0
A17: =Dashboard!A19 -> JULIO | B17: =Dashboard!B19 -> 0 | C17: =IFERROR(AVERAGEIF(Dashboard!$B$13:$B$24,">0")*(1+$B$4),0) -> 363000 | D17: =IFERROR(B17/C17,0) -> 0 | E17: =Dashboard!E19 -> 0 | F17: =C17*$B$5 -> 72600 | G17: =E17-F17 -> -72600 | H17: =IFERROR($B$7/SUMPRODUCT(Dashboard!$E$31:$E$38,'Menu Productos'!$H$5:$H$12),0) -> 0
A18: =Dashboard!A20 -> AGOSTO | B18: =Dashboard!B20 -> 0 | C18: =IFERROR(AVERAGEIF(Dashboard!$B$13:$B$24,">0")*(1+$B$4),0) -> 363000 | D18: =IFERROR(B18/C18,0) -> 0 | E18: =Dashboard!E20 -> 0 | F18: =C18*$B$5 -> 72600 | G18: =E18-F18 -> -72600 | H18: =IFERROR($B$7/SUMPRODUCT(Dashboard!$E$31:$E$38,'Menu Productos'!$H$5:$H$12),0) -> 0
A19: =Dashboard!A21 -> SEPTIEMBRE | B19: =Dashboard!B21 -> 0 | C19: =IFERROR(AVERAGEIF(Dashboard!$B$13:$B$24,">0")*(1+$B$4),0) -> 363000 | D19: =IFERROR(B19/C19,0) -> 0 | E19: =Dashboard!E21 -> 0 | F19: =C19*$B$5 -> 72600 | G19: =E19-F19 -> -72600 | H19: =IFERROR($B$7/SUMPRODUCT(Dashboard!$E$31:$E$38,'Menu Productos'!$H$5:$H$12),0) -> 0
A20: =Dashboard!A22 -> OCTUBRE | B20: =Dashboard!B22 -> 0 | C20: =IFERROR(AVERAGEIF(Dashboard!$B$13:$B$24,">0")*(1+$B$4),0) -> 363000 | D20: =IFERROR(B20/C20,0) -> 0 | E20: =Dashboard!E22 -> 0 | F20: =C20*$B$5 -> 72600 | G20: =E20-F20 -> -72600 | H20: =IFERROR($B$7/SUMPRODUCT(Dashboard!$E$31:$E$38,'Menu Productos'!$H$5:$H$12),0) -> 0
A21: =Dashboard!A23 -> NOVIEMBRE | B21: =Dashboard!B23 -> 0 | C21: =IFERROR(AVERAGEIF(Dashboard!$B$13:$B$24,">0")*(1+$B$4),0) -> 363000 | D21: =IFERROR(B21/C21,0) -> 0 | E21: =Dashboard!E23 -> 0 | F21: =C21*$B$5 -> 72600 | G21: =E21-F21 -> -72600 | H21: =IFERROR($B$7/SUMPRODUCT(Dashboard!$E$31:$E$38,'Menu Productos'!$H$5:$H$12),0) -> 0
A22: =Dashboard!A24 -> DICIEMBRE | B22: =Dashboard!B24 -> 0 | C22: =IFERROR(AVERAGEIF(Dashboard!$B$13:$B$24,">0")*(1+$B$4),0) -> 363000 | D22: =IFERROR(B22/C22,0) -> 0 | E22: =Dashboard!E24 -> 0 | F22: =C22*$B$5 -> 72600 | G22: =E22-F22 -> -72600 | H22: =IFERROR($B$7/SUMPRODUCT(Dashboard!$E$31:$E$38,'Menu Productos'!$H$5:$H$12),0) -> 0
A23: TOTAL / PROMEDIO | B23: =SUM(B11:B22) -> 330000 | C23: =SUM(C11:C22) -> 4356000 | D23: =IFERROR(B23/C23,0) -> 0.075757576 | E23: =SUM(E11:E22) -> 54636 | F23: =SUM(F11:F22) -> 871200 | G23: =SUM(G11:G22) -> -816564 | H23: =AVERAGE(H11:H22) -> 0

Sheet Chart Data
A1: MES | B1: VENTAS | C1: COSTOS | D1: GASTOS | E1: GANANCIA
A2: =Dashboard!A13 -> ENERO | B2: =IF(SUM(Dashboard!B13:D13)=0,NA(),Dashboard!B13) -> 330000 | C2: =IF(SUM(Dashboard!B13:D13)=0,NA(),Dashboard!C13) -> 275364 | D2: =IF(SUM(Dashboard!B13:D13)=0,NA(),Dashboard!D13) -> 0 | E2: =IF(SUM(Dashboard!B13:D13)=0,NA(),Dashboard!E13) -> 54636
A3: =Dashboard!A14 -> FEBRERO | B3: =IF(SUM(Dashboard!B14:D14)=0,NA(),Dashboard!B14) -> #N/A | C3: =IF(SUM(Dashboard!B14:D14)=0,NA(),Dashboard!C14) -> #N/A | D3: =IF(SUM(Dashboard!B14:D14)=0,NA(),Dashboard!D14) -> #N/A | E3: =IF(SUM(Dashboard!B14:D14)=0,NA(),Dashboard!E14) -> #N/A
A4: =Dashboard!A15 -> MARZO | B4: =IF(SUM(Dashboard!B15:D15)=0,NA(),Dashboard!B15) -> #N/A | C4: =IF(SUM(Dashboard!B15:D15)=0,NA(),Dashboard!C15) -> #N/A | D4: =IF(SUM(Dashboard!B15:D15)=0,NA(),Dashboard!D15) -> #N/A | E4: =IF(SUM(Dashboard!B15:D15)=0,NA(),Dashboard!E15) -> #N/A
A5: =Dashboard!A16 -> ABRIL | B5: =IF(SUM(Dashboard!B16:D16)=0,NA(),Dashboard!B16) -> #N/A | C5: =IF(SUM(Dashboard!B16:D16)=0,NA(),Dashboard!C16) -> #N/A | D5: =IF(SUM(Dashboard!B16:D16)=0,NA(),Dashboard!D16) -> #N/A | E5: =IF(SUM(Dashboard!B16:D16)=0,NA(),Dashboard!E16) -> #N/A
A6: =Dashboard!A17 -> MAYO | B6: =IF(SUM(Dashboard!B17:D17)=0,NA(),Dashboard!B17) -> #N/A | C6: =IF(SUM(Dashboard!B17:D17)=0,NA(),Dashboard!C17) -> #N/A | D6: =IF(SUM(Dashboard!B17:D17)=0,NA(),Dashboard!D17) -> #N/A | E6: =IF(SUM(Dashboard!B17:D17)=0,NA(),Dashboard!E17) -> #N/A
A7: =Dashboard!A18 -> JUNIO | B7: =IF(SUM(Dashboard!B18:D18)=0,NA(),Dashboard!B18) -> #N/A | C7: =IF(SUM(Dashboard!B18:D18)=0,NA(),Dashboard!C18) -> #N/A | D7: =IF(SUM(Dashboard!B18:D18)=0,NA(),Dashboard!D18) -> #N/A | E7: =IF(SUM(Dashboard!B18:D18)=0,NA(),Dashboard!E18) -> #N/A
A8: =Dashboard!A19 -> JULIO | B8: =IF(SUM(Dashboard!B19:D19)=0,NA(),Dashboard!B19) -> #N/A | C8: =IF(SUM(Dashboard!B19:D19)=0,NA(),Dashboard!C19) -> #N/A | D8: =IF(SUM(Dashboard!B19:D19)=0,NA(),Dashboard!D19) -> #N/A | E8: =IF(SUM(Dashboard!B19:D19)=0,NA(),Dashboard!E19) -> #N/A
A9: =Dashboard!A20 -> AGOSTO | B9: =IF(SUM(Dashboard!B20:D20)=0,NA(),Dashboard!B20) -> #N/A | C9: =IF(SUM(Dashboard!B20:D20)=0,NA(),Dashboard!C20) -> #N/A | D9: =IF(SUM(Dashboard!B20:D20)=0,NA(),Dashboard!D20) -> #N/A | E9: =IF(SUM(Dashboard!B20:D20)=0,NA(),Dashboard!E20) -> #N/A
A10: =Dashboard!A21 -> SEPTIEMBRE | B10: =IF(SUM(Dashboard!B21:D21)=0,NA(),Dashboard!B21) -> #N/A | C10: =IF(SUM(Dashboard!B21:D21)=0,NA(),Dashboard!C21) -> #N/A | D10: =IF(SUM(Dashboard!B21:D21)=0,NA(),Dashboard!D21) -> #N/A | E10: =IF(SUM(Dashboard!B21:D21)=0,NA(),Dashboard!E21) -> #N/A
A11: =Dashboard!A22 -> OCTUBRE | B11: =IF(SUM(Dashboard!B22:D22)=0,NA(),Dashboard!B22) -> #N/A | C11: =IF(SUM(Dashboard!B22:D22)=0,NA(),Dashboard!C22) -> #N/A | D11: =IF(SUM(Dashboard!B22:D22)=0,NA(),Dashboard!D22) -> #N/A | E11: =IF(SUM(Dashboard!B22:D22)=0,NA(),Dashboard!E22) -> #N/A
A12: =Dashboard!A23 -> NOVIEMBRE | B12: =IF(SUM(Dashboard!B23:D23)=0,NA(),Dashboard!B23) -> #N/A | C12: =IF(SUM(Dashboard!B23:D23)=0,NA(),Dashboard!C23) -> #N/A | D12: =IF(SUM(Dashboard!B23:D23)=0,NA(),Dashboard!D23) -> #N/A | E12: =IF(SUM(Dashboard!B23:D23)=0,NA(),Dashboard!E23) -> #N/A
A13: =Dashboard!A24 -> DICIEMBRE | B13: =IF(SUM(Dashboard!B24:D24)=0,NA(),Dashboard!B24) -> #N/A | C13: =IF(SUM(Dashboard!B24:D24)=0,NA(),Dashboard!C24) -> #N/A | D13: =IF(SUM(Dashboard!B24:D24)=0,NA(),Dashboard!D24) -> #N/A | E13: =IF(SUM(Dashboard!B24:D24)=0,NA(),Dashboard!E24) -> #N/A

Sheet Guía y Reporte
A1: GUÍA Y REPORTE DEL SISTEMA
A2: Manual práctico para cargar datos, controlar la caja y leer los resultados del negocio
A4: ESTADO ACTUAL — se actualiza automáticamente
A5: AÑO DEL MODELO | C5: VENTAS ACUMULADAS | E5: GANANCIA NETA | G5: CIERRES A REVISAR
A6: =Dashboard!B2 -> 2026 | C6: =Dashboard!A5 -> 330000 | E6: =Dashboard!D5 -> 54636 | G6: =Dashboard!M5 -> 0
A9: ORDEN RECOMENDADO DE USO
A11: PASO | B11: QUÉ HACER | E11: HOJA | G11: RESULTADO
A12: 1. Configurar menú | B12: Actualizar costos, extras, costo operativo y precios cuando cambien. | E12: Menu Productos | G12: Costos, utilidad y márgenes correctos.
A13: 2. Definir objetivos | B13: Revisar crecimiento, margen objetivo, tolerancia de caja y gastos fijos. | E13: Metas y Control | G13: Metas y punto de equilibrio actualizados.
A14: 3. Registrar el día | B14: Cargar cantidades vendidas, gastos, cobros y observaciones. | E14: Registro Diario | G14: Cierre diario completo y validado.
A15: 4. Analizar | B15: Revisar ventas, ganancia, productos, medios de cobro y alertas. | E15: Dashboard | G15: Decisiones con información consolidada.
A16: MAPA DE HOJAS
A17: HOJA | B17: FUNCIÓN | E17: QUÉ SE EDITA | G17: FRECUENCIA
A18: Dashboard | B18: Resume el año, los meses, productos, cobros y controles. | E18: Solo el año en B2. | G18: Consulta diaria/semanal
A19: Registro Diario | B19: Registra cada cierre y calcula venta, costo, ganancia y diferencia de caja. | E19: Cantidades, gastos, cobros y observaciones. | G19: Todos los días
A20: Menu Productos | B20: Define la economía unitaria de cada producto. | E20: Costos base, extras, costo operativo y precio. | G20: Cuando cambien precios/costos
A21: Metas y Control | B21: Compara resultados reales contra objetivos y calcula brechas. | E21: Crecimiento, margen, tolerancia y gastos fijos. | G21: Mensual
A22: Chart Data | B22: Alimenta el gráfico de evolución mensual. | E22: Nada: es una hoja técnica oculta. | G22: Automática
A24: CÓMO HACER EL CIERRE DIARIO
A25: ORDEN | B25: CAMPO | E25: QUÉ CARGAR | G25: CONTROL
A26: 1 | B26: Productos (C:J) | E26: Unidades vendidas de cada producto. | G26: TOTAL UNIDADES se calcula solo.
A27: 2 | B27: GASTOS (N) | E27: Egresos pagados durante el día. | G27: Reducen la ganancia y el importe esperado en caja.
A28: 3 | B28: EFECTIVO / TRANSFERENCIA / MERCADO PAGO (P:R) | E28: Monto realmente cobrado por cada medio. | G28: TOTAL COBRADO se suma automáticamente.
A29: 4 | B29: OBSERVACIONES (U) | E29: Aclaraciones de faltantes, devoluciones o movimientos especiales. | G29: Ayuda a justificar diferencias.
A30: 5 | B30: ESTADO (V) | E30: No se carga: revisar el resultado automático. | G30: OK = cierre correcto; REVISAR CAJA = existe diferencia.
A31: No editar | B31: FECHA, MES, K:O, S:T y V | E31: Son columnas calculadas por el sistema. | G31: Modificar fórmulas rompe el reporte.
A33: CÁLCULOS CLAVE DEL SISTEMA
A34: INDICADOR | B34: CÁLCULO | E34: QUÉ SIGNIFICA | G34: USO
A35: Venta total | B35: Unidades × precio de venta, sumado por producto. | E35: Facturación teórica del día. | G35: Control comercial
A36: Costo total | B36: Unidades × costo total unitario. | E36: Costo asociado a lo vendido. | G36: Rentabilidad
A37: Ganancia neta | B37: Venta total − costo total − gastos. | E37: Resultado después de costos y gastos diarios. | G37: Decisión financiera
A38: Total cobrado | B38: Efectivo + transferencia + Mercado Pago. | E38: Dinero informado en el cierre. | G38: Conciliación
A39: Diferencia de caja | B39: Total cobrado − (venta total − gastos). | E39: Cero o dentro de la tolerancia indica cierre correcto. | G39: Detección de errores
A40: Margen neto | B40: Ganancia neta ÷ ventas. | E40: Porcentaje de cada peso vendido que queda como ganancia. | G40: Seguimiento de desempeño
A42: ESTADOS Y ALERTAS
A43: ESTADO | B43: CUÁNDO APARECE | E43: ACCIÓN RECOMENDADA | G43: PRIORIDAD
A44: OK | B44: La diferencia está dentro de la tolerancia definida. | E44: Cerrar el día y conservar comprobantes. | G44: Normal
A45: REVISAR CAJA | B45: La diferencia supera la tolerancia. | E45: Revisar cobros, gastos, cantidades y observaciones. | G45: Alta
A46: SIN MOVIMIENTO | B46: No hay unidades, gastos ni cobros. | E46: Confirmar que el local no operó ese día. | G46: Baja
A47: FUTURO | B47: La fecha todavía no ocurrió. | E47: No cargar información anticipada. | G47: Informativa
...
